Workbook

Sheet Cost Estimate
A1: COST ESTIMATE - BAHUNDANDA SOUTH SPUR RURAL ELECTRIFICATION
A2: Rates in NPR excluding VAT. Yellow rate = indicative market rate (no current published rate found online): replace with the Lamjung district rate or NEA rate before submission.
A4: S.No. | B4: Particulars | C4: Quantity | D4: Unit Cost (Rs.) | E4: Cost (Rs.)
A5: 1 | B5: Conductors | C5: Length (km) with sag | D5: Rs./km
A6: i. | B6: ACSR Squirrel | C6: =Conductors!I17 -> 4.0161 | D6: 80000 | E6: =C6*D6 -> 321288
A7: ii. | B7: ACSR Gopher | C7: =Conductors!I18 -> 0.6303 | D7: 100000 | E7: =C7*D7 -> 63030
A8: 2 | B8: Poles | C8: Quantity | D8: Rs./no
A9: i. | B9: Steel tubular pole 11 m | C9: =SUMIF('Quantities by Pole'!$E$4:$E$62,11,'Quantities by Pole'!$D$4:$D$62) -> 7 | D9: 32000 | E9: =C9*D9 -> 224000
A10: ii. | B10: Steel tubular pole 8 m (LV) | C10: =SUMIF('Quantities by Pole'!$E$4:$E$62,8,'Quantities by Pole'!$D$4:$D$62) -> 53 | D10: 16000 | E10: =C10*D10 -> 848000
A11: 3 | B11: Stay set | C11: Quantity | D11: Rs./set
A12: i. | B12: HT stay set | C12: ='Quantities by Pole'!H63 -> 4 | D12: 4500 | E12: =C12*D12 -> 18000
A13: ii. | B13: LT stay set | C13: ='Quantities by Pole'!G63 -> 38 | D13: 3500 | E13: =C13*D13 -> 133000
A14: 4 | B14: Insulators and fittings | C14: Quantity | D14: Rs./no
A15: i. | B15: Shackle insulator (medium) | C15: ='Quantities by Pole'!I63 -> 43 | D15: 70 | E15: =C15*D15 -> 3010
A16: ii. | B16: Shackle insulator (large) | C16: ='Quantities by Pole'!J63 -> 106 | D16: 110 | E16: =C16*D16 -> 11660
A17: iii. | B17: D-iron set (with bolts) | C17: ='Quantities by Pole'!K63 -> 149 | D17: 280 | E17: =C17*D17 -> 41720
A18: iv. | B18: 11 kV pin insulator with GI pin | C18: ='Quantities by Pole'!L63 -> 12 | D18: 750 | E18: =C18*D18 -> 9000
A19: v. | B19: 11 kV disc (strain) insulator set with fittings | C19: ='Quantities by Pole'!M63 -> 18 | D19: 2200 | E19: =C19*D19 -> 39600
A20: vi. | B20: 11 kV cross arm set (channel, with clamps) | C20: ='Quantities by Pole'!N63 -> 8 | D20: 3000 | E20: =C20*D20 -> 24000
A21: 5 | B21: Lightning arrestors | C21: Quantity | D21: Rs./no
A22: i. | B22: 0.5 kV, ZnO | C22: ='Quantities by Pole'!O63 -> 11 | D22: 1000 | E22: =C22*D22 -> 11000
A23: ii. | B23: 9 kV, ZnO | C23: ='Quantities by Pole'!P63 -> 3 | D23: 3500 | E23: =C23*D23 -> 10500
A24: 6 | B24: Earthing set | C24: Quantity | D24: Rs./set
A25: i. | B25: Earthing set | C25: ='Quantities by Pole'!Q63 -> 12 | D25: 6000 | E25: =C25*D25 -> 72000
A26: 8 | B26: Transformer and switchgear | C26: Quantity | D26: Rs./no
A27: i. | B27: Transformer 25 kVA, 3-phase, 11 kV/433 V, Dyn11 | C27: 1 | D27: 280000 | E27: =C27*D27 -> 280000
A28: ii. | B28: 11 kV air break switch, 3-pole, 400 A | C28: 1 | D28: 50000 | E28: =C28*D28 -> 50000
A29: iii. | B29: 11 kV drop-out fuse set (3 nos) at T1 | C29: 1 | D29: 18000 | E29: =C29*D29 -> 18000
A30: iv. | B30: LV distribution box with MCCBs | C30: 1 | D30: 30000 | E30: =C30*D30 -> 30000
B32: Total material cost (A) | E32: =SUM(E6,E7,E9,E10,E12,E13,E15,E16,E17,E18,E19,E20,E22,E23,E25,E27,E28,E29,E30) -> 2207808
B33: Labour, erection and stringing (B) = % of A | C33: 0.2 | E33: =C33*E32 -> 441561.6
B34: Transportation and porterage (C) = % of A | C34: 0.1 | E34: =C34*E32 -> 220780.8
B35: Sub-total (A + B + C) | E35: =E32+E33+E34 -> 2870150.4
B36: VAT | C36: 0.13 | E36: =C36*E35 -> 373119.55
B37: Total including VAT | E37: =E35+E36 -> 3243270
B38: Contingencies | C38: 0.05 | E38: =C38*E37 -> 162163.5
B39: GRAND TOTAL | E39: =E37+E38 -> 3405433.4
B41: Cost per household (68 households) | E41: =E39/68 -> 50079.904
B42: Cost per km of line (11 kV + LV route, km) | C42: =Conductors!E16/1000 -> 1.75 | E42: =E39/C42 -> 1945962
A44: Notes
...

Sheet Conductors
A1: CONDUCTOR QUANTITIES BY REACH
A2: Allowance for sag, jumpers and wastage (x distance): | F2: 1.1
A4: From | B4: To | C4: Reach | D4: Phase | E4: Distance (m) | F4: No. of wires | G4: Conductor | H4: Route length with sag (m) | I4: Conductor length with sag (km)
A5: HT00 | B5: T1 | C5: HT00-T1 | D5: 3 (11 kV) | E5: 269 | F5: 3 | G5: Squirrel | H5: =E5*$F$2 -> 295.9 | I5: =H5*F5/1000 -> 0.8877
A6: T1 | B6: A08 | C6: T1-A08 | D6: 2 (y,b) | E6: 264 | F6: 3 | G6: Squirrel | H6: =E6*$F$2 -> 290.4 | I6: =H6*F6/1000 -> 0.8712
A7: A08 | B7: A105 | C7: A08-A105 | D7: 1 (b) | E7: 131 | F7: 2 | G7: Squirrel | H7: =E7*$F$2 -> 144.1 | I7: =H7*F7/1000 -> 0.2882
A8: A08 | B8: A207 | C8: A08-A207 | D8: 1 (y) | E8: 200 | F8: 2 | G8: Squirrel | H8: =E8*$F$2 -> 220 | I8: =H8*F8/1000 -> 0.44
A9: T1 | B9: B07 | C9: T1-B07 | D9: 1 (b) | E9: 164 | F9: 2 | G9: Squirrel | H9: =E9*$F$2 -> 180.4 | I9: =H9*F9/1000 -> 0.3608
A10: T1 | B10: C07 | C10: T1-C07 | D10: 1 (r) | E10: 148 | F10: 2 | G10: Squirrel | H10: =E10*$F$2 -> 162.8 | I10: =H10*F10/1000 -> 0.3256
A11: C01 | B11: C104 | C11: C01-C104 | D11: 1 (r) | E11: 107 | F11: 2 | G11: Squirrel | H11: =E11*$F$2 -> 117.7 | I11: =H11*F11/1000 -> 0.2354
A12: T1 | B12: D06 | C12: T1-D06 | D12: 2 (r,y) | E12: 191 | F12: 3 | G12: Gopher | H12: =E12*$F$2 -> 210.1 | I12: =H12*F12/1000 -> 0.6303
A13: D06 | B13: D104 | C13: D06-D104 | D13: 1 (r) | E13: 116 | F13: 2 | G13: Squirrel | H13: =E13*$F$2 -> 127.6 | I13: =H13*F13/1000 -> 0.2552
A14: D06 | B14: D204 | C14: D06-D204 | D14: 1 (y) | E14: 127 | F14: 2 | G14: Squirrel | H14: =E14*$F$2 -> 139.7 | I14: =H14*F14/1000 -> 0.2794
A15: D202 | B15: D301 | C15: D202-D301 | D15: 1 (y) | E15: 33 | F15: 2 | G15: Squirrel | H15: =E15*$F$2 -> 36.3 | I15: =H15*F15/1000 -> 0.0726
C16: Total | E16: =SUM(E5:E15) -> 1750 | H16: =SUM(H5:H15) -> 1925 | I16: =SUM(I5:I15) -> 4.6464
C17: of which Squirrel | G17: Squirrel | I17: =SUMIF($G$5:$G$15,G17,$I$5:$I$15) -> 4.0161
C18: of which Gopher | G18: Gopher | I18: =SUMIF($G$5:$G$15,G18,$I$5:$I$15) -> 0.6303
A20: Conductor per reach is an input (blue): type Squirrel or Gopher. Wires: 11 kV = 3; LV two-phase = 3; LV single-phase = 2.

Sheet Quantities by Pole
A1: MATERIAL QUANTITIES BY POLE
A3: Pole ID | B3: Reach | C3: Line | D3: Poles (nos) | E3: Pole height (m) | F3: Wires | G3: LT stay sets | H3: HT stay sets | I3: Shackle (medium) | J3: Shackle (large) | K3: D-iron sets | L3: 11 kV pin insulators | M3: 11 kV disc sets | N3: 11 kV cross arms | O3: LA 0.5 kV | P3: LA 9 kV | Q3: Earthing sets
A4: HT00 | B4: HT00-T1 | C4: 11 kV | D4: 1 | E4: 11 | F4: 3 | G4: 0 | H4: 1 | I4: 0 | J4: 0 | K4: =I4+J4 -> 0 | L4: 0 | M4: 3 | N4: 1 | O4: 0 | P4: 0 | Q4: 1
A5: HT01 | B5: HT00-T1 | C5: 11 kV | D5: 1 | E5: 11 | F5: 3 | G5: 0 | H5: 1 | I5: 0 | J5: 0 | K5: =I5+J5 -> 0 | L5: 3 | M5: 6 | N5: 2 | O5: 0 | P5: 0 | Q5: 0
A6: HT02 | B6: HT00-T1 | C6: 11 kV | D6: 1 | E6: 11 | F6: 3 | G6: 0 | H6: 0 | I6: 0 | J6: 0 | K6: =I6+J6 -> 0 | L6: 3 | M6: 0 | N6: 1 | O6: 0 | P6: 0 | Q6: 0
A7: HT03 | B7: HT00-T1 | C7: 11 kV | D7: 1 | E7: 11 | F7: 3 | G7: 0 | H7: 0 | I7: 0 | J7: 0 | K7: =I7+J7 -> 0 | L7: 3 | M7: 0 | N7: 1 | O7: 0 | P7: 0 | Q7: 0
A8: HT04 | B8: HT00-T1 | C8: 11 kV | D8: 1 | E8: 11 | F8: 3 | G8: 0 | H8: 1 | I8: 0 | J8: 0 | K8: =I8+J8 -> 0 | L8: 3 | M8: 6 | N8: 2 | O8: 0 | P8: 0 | Q8: 0
A9: T1 | B9: T1 structure | C9: 11 kV / transformer | D9: 2 | E9: 11 | F9: 3 | G9: 0 | H9: 1 | I9: 0 | J9: 10 | K9: =I9+J9 -> 10 | L9: 0 | M9: 3 | N9: 1 | O9: 3 | P9: 3 | Q9: 3
A10: A01 | B10: T1-A08 | C10: LV | D10: 1 | E10: 8 | F10: 3 | G10: 0 | H10: 0 | I10: 3 | J10: 0 | K10: =I10+J10 -> 3 | L10: 0 | M10: 0 | N10: 0 | O10: 0 | P10: 0 | Q10: 0
A11: A02 | B11: T1-A08 | C11: LV | D11: 1 | E11: 8 | F11: 3 | G11: 0 | H11: 0 | I11: 3 | J11: 0 | K11: =I11+J11 -> 3 | L11: 0 | M11: 0 | N11: 0 | O11: 0 | P11: 0 | Q11: 0
A12: A03 | B12: T1-A08 | C12: LV | D12: 1 | E12: 8 | F12: 3 | G12: 1 | H12: 0 | I12: 0 | J12: 3 | K12: =I12+J12 -> 3 | L12: 0 | M12: 0 | N12: 0 | O12: 0 | P12: 0 | Q12: 0
A13: A04 | B13: T1-A08 | C13: LV | D13: 1 | E13: 8 | F13: 3 | G13: 1 | H13: 0 | I13: 0 | J13: 3 | K13: =I13+J13 -> 3 | L13: 0 | M13: 0 | N13: 0 | O13: 0 | P13: 0 | Q13: 0
A14: A05 | B14: T1-A08 | C14: LV | D14: 1 | E14: 8 | F14: 3 | G14: 1 | H14: 0 | I14: 0 | J14: 3 | K14: =I14+J14 -> 3 | L14: 0 | M14: 0 | N14: 0 | O14: 0 | P14: 0 | Q14: 0
A15: A06 | B15: T1-A08 | C15: LV | D15: 1 | E15: 8 | F15: 3 | G15: 1 | H15: 0 | I15: 0 | J15: 3 | K15: =I15+J15 -> 3 | L15: 0 | M15: 0 | N15: 0 | O15: 0 | P15: 0 | Q15: 0
... A62: D301 | B62: D202-D301 | C62: LV | D62: 1 | E62: 8 | F62: 2 | G62: 1 | H62: 0 | I62: 0 | J62: 2 | K62: =I62+J62 -> 2 | L62: 0 | M62: 0 | N62: 0 | O62: 1 | P62: 0 | Q62: 1
A63: Total | D63: =SUM(D4:D62) -> 60 | G63: =SUM(G4:G62) -> 38 | H63: =SUM(H4:H62) -> 4 | I63: =SUM(I4:I62) -> 43 | J63: =SUM(J4:J62) -> 106 | K63: =SUM(K4:K62) -> 149 | L63: =SUM(L4:L62) -> 12 | M63: =SUM(M4:M62) -> 18 | N63: =SUM(N4:N62) -> 8 | ... Q63: =SUM(Q4:Q62) -> 12
A65: Counting rules
A66: LV (each wire on a shackle insulator with D-iron): tangent pole = 1 medium shackle per wire; angle 10-60 deg = 1 large per wire; angle > 60 deg = 2 large per wire; dead-end = 1 large per wire; tee-off = large for the incoming wires + the wires of each branch starting there. D-iron set = 1 per shackle.
A67: T1 structure: LV terminations of the four outgoing feeders on large shackles (A 3 + B 2 + C 2 + D 3 wires); 3 disc sets + 1 cross arm (11 kV terminal); 3 x 9 kV LAs (HV side), 3 x 0.5 kV LAs (LV side); 3 earthing sets (neutral, body, LA).
A68: 11 kV: tangent = 3 pin insulators + 1 cross arm; angle = 6 disc sets (double dead-end) + 3 pin insulators for jumpers + 2 cross arms; tap-off HT00 = 3 disc sets + 1 cross arm + earthing for the ABS.
A69: Each LV dead-end: 1 x 0.5 kV LA per phase wire and 1 earthing set. Stay sets as in the pole table.
